Workbook

Sheet SET100
A1: ลำดับ | B1: Symbol | C1: Market Cap (ล้านบาท) | D1: กลุ่มอุตสาหกรรม | E1: P/E | F1: P/BV | G1: D/E | H1: Yield | I1: EPS | J1: ราคาสิ้นปี 68 ณ วันที่ | K1: ราคาสิ้นปี 68 | L1: ราคาล่าสุด ณ วันที่ | M1: ราคาล่าสุด | N1: ส่วนต่าง (%) | O1: SET50 | P1: SETHD | Q1: ครั้ง/ปี | R1: วันปันผลปี 68 | S1: ประมาณการปี 69
A2: 1 | B2: DELTA | C2: 1215000 | D2: อิเล็กทรอนิกส์ | E2: 65.4 | F2: 18.6 | G2: 0.25 | H2: 0.005 | I2: 1.48 | J2: 25202 | K2: 95 | L2: 25244 | M2: 97.5 | N2: 0.0263 | O2: 1 | Q2: 1 | R2: 24896 | S2: 25261
A3: 2 | B3: PTT | C3: 971000 | D3: พลังงาน | E3: 9.45 | F3: 0.84 | G3: 0.88 | H3: 0.058 | I3: 3.65 | J3: 25202 | K3: 34.25 | L3: 25244 | M3: 34 | N3: -0.0073 | O3: 1 | P3: 1 | Q3: 2 | R3: 25085 | S3: 25267
A4: 3 | B4: AOT | C4: 878000 | D4: ขนส่ง | E4: 47.8 | F4: 7.75 | G4: 1.1 | H4: 0.011 | I4: 1.25 | J4: 25202 | K4: 61.5 | L4: 25244 | M4: 61.25 | N4: -0.0041 | O4: 1 | Q4: 1 | R4: 24881 | S4: 25246
A5: 4 | B5: ADVANC | C5: 728000 | D5: ICT | E5: 21.5 | F5: 7.6 | G5: 1.45 | H5: 0.039 | I5: 9.85 | J5: 25202 | K5: 240 | L5: 25244 | M5: 245 | N5: 0.0208 | O5: 1 | P5: 1 | Q5: 2 | R5: 25069 | S5: 25254
A6: 5 | B6: GULF | C6: 639000 | D6: พลังงาน | E6: 35.2 | F6: 4.75 | G6: 1.8 | H6: 0.012 | I6: 1.35 | J6: 25202 | K6: 55 | L6: 25244 | M6: 54.5 | N6: -0.0091 | O6: 1 | Q6: 1 | R6: 24897 | S6: 25262
A7: 6 | B7: PTTEP | C7: 601000 | D7: พลังงาน | E7: 8.15 | F7: 1.14 | G7: 0.3 | H7: 0.063 | I7: 18.55 | J7: 25202 | K7: 152 | L7: 25244 | M7: 151 | N7: -0.0066 | O7: 1 | P7: 1 | Q7: 2 | R7: 25077 | S7: 25245
A8: 7 | B8: CPALL | C8: 583000 | D8: พาณิชย์ | E8: 28.6 | F8: 6.25 | G8: 1.95 | H8: 0.019 | I8: 2.18 | J8: 25202 | K8: 64 | L8: 25244 | M8: 65 | N8: 0.0156 | O8: 1 | Q8: 1 | R8: 24965 | S8: 25331
A9: 8 | B9: BDMS | C9: 461000 | D9: การแพทย์ | E9: 30.8 | F9: 4.95 | G9: 0.4 | H9: 0.022 | I9: 0.96 | J9: 25202 | K9: 28.5 | L9: 25244 | M9: 29 | N9: 0.0175 | O9: 1 | Q9: 2 | R9: 25093 | S9: 25272
A10: 9 | B10: KBANK | C10: 338000 | D10: ธนาคาร | E10: 8.35 | F10: 0.66 | G10: N/A | H10: 0.043 | I10: 18.25 | J10: 25202 | K10: 141 | L10: 25244 | M10: 142.5 | N10: 0.0106 | O10: 1 | P10: 1 | Q10: 2 | R10: 25092 | S10: 25309
A11: 10 | B11: BBL | C11: 307000 | D11: ธนาคาร | E11: 7.15 | F11: 0.56 | G11: N/A | H11: 0.046 | I11: 21.45 | J11: 25202 | K11: 159 | L11: 25244 | M11: 161 | N11: 0.0126 | O11: 1 | P11: 1 | Q11: 2 | R11: 25085 | S11: 25315
A12: 11 | B12: SCB | C12: 289000 | D12: ธนาคาร | E12: 9.1 | F12: 0.76 | G12: N/A | H12: 0.076 | I12: 13.55 | J12: 25202 | K12: 108 | L12: 25244 | M12: 111 | N12: 0.0278 | O12: 1 | P12: 1 | Q12: 2 | R12: 25061 | S12: 25310
A13: 12 | B13: SCC | C13: 272000 | D13: วัสดุก่อสร้าง | E13: 15.4 | F13: 0.94 | G13: 1.15 | H13: 0.029 | I13: 15.15 | J13: 25202 | K13: 231 | L13: 25244 | M13: 227 | N13: -0.0173 | O13: 1 | P13: 1 | Q13: 2 | R13: 25058 | S13: 25440
A14: 13 | B14: CPAXT | C14: 271000 | D14: พาณิชย์ | E14: 31.9 | F14: 1.92 | G14: 0.85 | H14: 0.016 | I14: 0.98 | J14: 25202 | K14: 25.5 | L14: 25244 | M14: 25.75 | N14: 0.0098 | O14: 1 | Q14: 2 | R14: 25071 | S14: 25437
A15: 14 | B15: KTB | C15: 262000 | D15: ธนาคาร | E15: 6.45 | F15: 0.62 | G15: N/A | H15: 0.053 | I15: 2.88 | J15: 25202 | K15: 18.5 | L15: 25244 | M15: 18.8 | N15: 0.0162 | O15: 1 | P15: 1 | Q15: 1 | R15: 24945 | S15: 25311
A16: 15 | B16: TRUE | C16: 243000 | D16: ICT | E16: 44.5 | F16: 3.15 | G16: 3.25 | H16: 0.013 | I16: 0.18 | J16: 25202 | K16: 6.95 | L16: 25244 | M16: 7.05 | N16: 0.0144 | O16: 1 | Q16: 1 | R16: 24910 | S16: 25274
A17: 16 | B17: CPN | C17: 226000 | D17: อสังหาฯ | E17: 18.2 | F17: 3.18 | G17: 0.95 | H17: 0.026 | I17: 3.62 | J17: 25202 | K17: 51 | L17: 25244 | M17: 50.5 | N17: -0.0098 | O17: 1 | Q17: 1 | R17: 24911 | S17: 25275
A18: 17 | B18: BH | C18: 167000 | D18: การแพทย์ | E18: 25.8 | F18: 5.15 | G18: 0.2 | H18: 0.019 | I18: 8.85 | J18: 25202 | K18: 205 | L18: 25244 | M18: 210 | N18: 0.0244 | O18: 1 | Q18: 2 | R18: 25076 | S18: 25274
A19: 18 | B19: TOP | C19: 142000 | D19: พลังงาน | E19: 7.45 | F19: 0.77 | G19: 1.05 | H19: 0.053 | I19: 7.18 | J19: 25202 | K19: 51.5 | L19: 25244 | M19: 50.75 | N19: -0.0146 | O19: 1 | P19: 1 | Q19: 2 | R19: 25092 | S19: 25259
A20: 19 | B20: IVL | C20: 126000 | D20: ปิโตรเคมี | E20: 14.3 | F20: 1.1 | G20: 1.35 | H20: 0.029 | I20: 1.82 | J20: 25202 | K20: 22.1 | L20: 25244 | M20: 22.5 | N20: 0.0181 | O20: 1 | P20: 1 | Q20: 4 | R20: 25170 | S20: 25343
A21: 20 | B21: TTB | C21: 139000 | D21: ธนาคาร | E21: 8.55 | F21: 0.79 | G21: N/A | H21: 0.059 | I21: 0.21 | J21: 25202 | K21: 1.42 | L21: 25244 | M21: 1.45 | N21: 0.0211 | O21: 1 | P21: 1 | Q21: 2 | R21: 25121 | S21: 25311
A22: 21 | B22: OR | C22: 133000 | D22: พลังงาน | E22: 18.2 | F22: 1.85 | G22: 0.75 | H22: 0.028 | I22: 1.05 | J22: 25202 | K22: 18.5 | L22: 25244 | M22: 18.2 | N22: -0.0162 | O22: 1 | Q22: 2 | R22: 25092 | S22: 25258
A23: 22 | B23: HMPRO | C23: 128000 | D23: พาณิชย์ | E23: 19.8 | F23: 4.2 | G23: 0.8 | H23: 0.032 | I23: 0.52 | J23: 25202 | K23: 9.8 | L23: 25244 | M23: 9.75 | N23: -0.0051 | O23: 1 | P23: 1 | Q23: 2 | R23: 25092 | S23: 25311
A24: 23 | B24: CPF | C24: 118000 | D24: อาหาร | E24: 15.1 | F24: 0.92 | G24: 1.65 | H24: 0.033 | I24: 1.55 | J24: 25202 | K24: 13.8 | L24: 25244 | M24: 14.2 | N24: 0.029 | O24: 1 | Q24: 2 | R24: 25079 | S24: 25328
A25: 24 | B25: BCP | C25: 112000 | D25: พลังงาน | E25: 6.45 | F25: 0.74 | G25: 1.4 | H25: 0.062 | I25: 5.85 | J25: 25202 | K25: 41 | L25: 25244 | M25: 40.5 | N25: -0.0122 | O25: 1 | P25: 1 | Q25: 2 | R25: 25092 | S25: 25266
A26: 25 | B26: GPSC | C26: 108000 | D26: พลังงาน | E26: 25.4 | F26: 1.45 | G26: 1.25 | H26: 0.025 | I26: 1.85 | J26: 25202 | K26: 38.25 | L26: 25244 | M26: 38.5 | N26: 0.0065 | O26: 1 | Q26: 2 | R26: 25092 | S26: 25258
A27: 26 | B27: WHA | C27: 103000 | D27: อสังหาฯ | E27: 16.8 | F27: 2.45 | G27: 1.1 | H27: 0.032 | I27: 0.32 | J27: 25202 | K27: 6.9 | L27: 25244 | M27: 7.05 | N27: 0.0217 | O27: 1 | P27: 1 | Q27: 2 | R27: 25163 | S27: 25335
A28: 27 | B28: LH | C28: 98000 | D28: อสังหาฯ | E28: 14.5 | F28: 1.9 | G28: 1.15 | H28: 0.062 | I28: 0.65 | J28: 25202 | K28: 8.2 | L28: 25244 | M28: 8 | N28: -0.0244 | O28: 1 | P28: 1 | Q28: 2 | R28: 25073 | S28: 25329
A29: 28 | B29: SCGP | C29: 90000 | D29: บรรจุภัณฑ์ | E29: 18.5 | F29: 1.45 | G29: 0.7 | H29: 0.028 | I29: 1.45 | J29: 25202 | K29: 28.5 | L29: 25244 | M29: 28.25 | N29: -0.0088 | O29: 1 | Q29: 2 | R29: 25072 | S29: 25296
A30: 29 | B30: KTC | C30: 82000 | D30: เงินทุน | E30: 15.4 | F30: 3.2 | G30: 2.1 | H30: 0.024 | I30: 2.85 | J30: 25202 | K30: 31.75 | L30: 25244 | M30: 32.25 | N30: 0.0157 | O30: 1 | Q30: 1 | R30: 24945 | S30: 25311
A31: 30 | B31: MTC | C31: 80000 | D31: เงินทุน | E31: 16.8 | F31: 3.1 | G31: 3.4 | H31: 0.013 | I31: 2.65 | J31: 25202 | K31: 37.5 | L31: 25244 | M31: 38.25 | N31: 0.02 | O31: 1 | Q31: 1 | R31: 24957 | S31: 25321
A32: 31 | B32: TISCO | C32: 71800 | D32: ธนาคาร | E32: 10.55 | F32: 1.96 | G32: N/A | H32: 0.079 | I32: 9.25 | J32: 25202 | K32: 89.5 | L32: 25244 | M32: 90 | N32: 0.0056 | O32: 1 | P32: 1 | Q32: 1 | R32: 24952 | S32: 25318
A33: 32 | B33: ITC | C33: 70000 | D33: อาหาร | E33: 21.8 | F33: 3.75 | G33: 0.15 | H33: 0.036 | I33: 1.05 | J33: 25202 | K33: 23.5 | L33: 25244 | M33: 24.1 | N33: 0.0255 | O33: 1 | Q33: 2 | R33: 25092 | S33: 25267
A34: 33 | B34: AWC | C34: 68000 | D34: อสังหาฯ | E34: 35.2 | F34: 1.8 | G34: 0.85 | H34: 0.005 | I34: 0.12 | J34: 25202 | K34: 2.15 | L34: 25244 | M34: 2.1 | N34: -0.0233 | O34: 1 | Q34: 1 | R34: 24980 | S34: 25344
A35: 34 | B35: SAWAD | C35: 65000 | D35: เงินทุน | E35: 11.5 | F35: 1.8 | G35: 2.5 | H35: 0.042 | I35: 3.5 | J35: 25202 | K35: 31.5 | L35: 25244 | M35: 32 | N35: 0.0159 | O35: 1 | P35: 1 | Q35: 1 | R35: 24960 | S35: 25326
A36: 35 | B36: KCE | C36: 62000 | D36: อิเล็กฯ | E36: 22.1 | F36: 3.4 | G36: 0.45 | H36: 0.021 | I36: 1.65 | J36: 25202 | K36: 31.5 | L36: 25244 | M36: 32.25 | N36: 0.0238 | O36: 1 | Q36: 2 | R36: 25071 | S36: 25282
A37: 36 | B37: HANA | C37: 60000 | D37: อิเล็กฯ | E37: 14.8 | F37: 1.35 | G37: 0.35 | H37: 0.032 | I37: 2.6 | J37: 25202 | K37: 32 | L37: 25244 | M37: 33.5 | N37: 0.0469 | O37: 1 | P37: 1 | Q37: 2 | R37: 25092 | S37: 25276
A38: 37 | B38: BGRIM | C38: 58000 | D38: พลังงาน | E38: 28.5 | F38: 1.95 | G38: 1.85 | H38: 0.018 | I38: 0.85 | J38: 25202 | K38: 18.5 | L38: 25244 | M38: 18.2 | N38: -0.0162 | O38: 1 | Q38: 2 | R38: 25085 | S38: 25274
A39: 38 | B39: EGCO | C39: 54000 | D39: พลังงาน | E39: 11.5 | F39: 0.55 | G39: 1.2 | H39: 0.058 | I39: 12.4 | J39: 25202 | K39: 102 | L39: 25244 | M39: 101.5 | N39: -0.0049 | O39: 1 | P39: 1 | Q39: 2 | R39: 25092 | S39: 25276
A40: 39 | B40: RATCH | C40: 51500 | D40: พลังงาน | E40: 10.8 | F40: 0.68 | G40: 1.05 | H40: 0.055 | I40: 3.1 | J40: 25202 | K40: 23.9 | L40: 25244 | M40: 24.1 | N40: 0.0084 | O40: 1 | P40: 1 | Q40: 2 | R40: 25092 | S40: 25281
...

Sheet GSymbol
A1: Seq | B1: ='SET100'!B1 -> Symbol | C1: ='SET100'!C1 -> Market Cap (ล้านบาท) | D1: ='SET100'!D1 -> กลุ่มอุตสาหกรรม | E1: ='SET100'!O1 -> SET50 | F1: ='SET100'!P1 -> SETHD
A2: ='SET100'!A2 -> 1 | B2: ='SET100'!B2 -> DELTA | C2: ='SET100'!C2 -> 1215000 | D2: ='SET100'!D2 -> อิเล็กทรอนิกส์ | E2: ='SET100'!O2 -> 1 | F2: ='SET100'!P2 -> 0
A3: ='SET100'!A3 -> 2 | B3: ='SET100'!B3 -> PTT | C3: ='SET100'!C3 -> 971000 | D3: ='SET100'!D3 -> พลังงาน | E3: ='SET100'!O3 -> 1 | F3: ='SET100'!P3 -> 1
A4: ='SET100'!A4 -> 3 | B4: ='SET100'!B4 -> AOT | C4: ='SET100'!C4 -> 878000 | D4: ='SET100'!D4 -> ขนส่ง | E4: ='SET100'!O4 -> 1 | F4: ='SET100'!P4 -> 0
A5: ='SET100'!A5 -> 4 | B5: ='SET100'!B5 -> ADVANC | C5: ='SET100'!C5 -> 728000 | D5: ='SET100'!D5 -> ICT | E5: ='SET100'!O5 -> 1 | F5: ='SET100'!P5 -> 1
A6: ='SET100'!A6 -> 5 | B6: ='SET100'!B6 -> GULF | C6: ='SET100'!C6 -> 639000 | D6: ='SET100'!D6 -> พลังงาน | E6: ='SET100'!O6 -> 1 | F6: ='SET100'!P6 -> 0
A7: ='SET100'!A7 -> 6 | B7: ='SET100'!B7 -> PTTEP | C7: ='SET100'!C7 -> 601000 | D7: ='SET100'!D7 -> พลังงาน | E7: ='SET100'!O7 -> 1 | F7: ='SET100'!P7 -> 1
A8: ='SET100'!A8 -> 7 | B8: ='SET100'!B8 -> CPALL | C8: ='SET100'!C8 -> 583000 | D8: ='SET100'!D8 -> พาณิชย์ | E8: ='SET100'!O8 -> 1 | F8: ='SET100'!P8 -> 0
A9: ='SET100'!A9 -> 8 | B9: ='SET100'!B9 -> BDMS | C9: ='SET100'!C9 -> 461000 | D9: ='SET100'!D9 -> การแพทย์ | E9: ='SET100'!O9 -> 1 | F9: ='SET100'!P9 -> 0
A10: ='SET100'!A10 -> 9 | B10: ='SET100'!B10 -> KBANK | C10: ='SET100'!C10 -> 338000 | D10: ='SET100'!D10 -> ธนาคาร | E10: ='SET100'!O10 -> 1 | F10: ='SET100'!P10 -> 1
A11: ='SET100'!A11 -> 10 | B11: ='SET100'!B11 -> BBL | C11: ='SET100'!C11 -> 307000 | D11: ='SET100'!D11 -> ธนาคาร | E11: ='SET100'!O11 -> 1 | F11: ='SET100'!P11 -> 1
A12: ='SET100'!A12 -> 11 | B12: ='SET100'!B12 -> SCB | C12: ='SET100'!C12 -> 289000 | D12: ='SET100'!D12 -> ธนาคาร | E12: ='SET100'!O12 -> 1 | F12: ='SET100'!P12 -> 1
A13: ='SET100'!A13 -> 12 | B13: ='SET100'!B13 -> SCC | C13: ='SET100'!C13 -> 272000 | D13: ='SET100'!D13 -> วัสดุก่อสร้าง | E13: ='SET100'!O13 -> 1 | F13: ='SET100'!P13 -> 1
... A101: ='SET100'!A101 -> 100 | B101: ='SET100'!B101 -> PLANB | C101: ='SET100'!C101 -> 5200 | D101: ='SET100'!D101 -> บริการ | E101: ='SET100'!O101 -> 0 | F101: ='SET100'!P101 -> 0
